Workbook

Sheet Annual
A1: Year | B1: 2020 | C1: 2021 | D1: 2022 | E1: 2023 | F1: 2024 | G1: 2024 | H1: =COUNTA($B1:G1)-1 -> 5 | I1: Calendar Years
B2: Value (L) | C2: Value (L) | D2: Value (L) | E2: Value (L) | F2: Value (L) | G2: Value (L) | H2: CAGR | I2: TOTAL
A3: NET WORTH
A4: Equity | B4: =Quarterly!B4 -> 45.920595 | C4: =Quarterly!$F4 -> 85.270469 | D4: =Quarterly!$J4 -> 104.01465 | E4: =Quarterly!$N4 -> 168.52674 | F4: =Quarterly!$R4 -> 233.86821 | G4: =Quarterly!$V4 -> 253.19622 | H4: =((G4/B4)^(1/$H$1)-1) -> 0.40698654
A5: Debt | B5: =Quarterly!B5 -> 32.53 | C5: =Quarterly!$F5 -> 40.56374 | D5: =Quarterly!$J5 -> 49.11703 | E5: =Quarterly!$N5 -> 58.18654 | F5: =Quarterly!$R5 -> 69.28894 | G5: =Quarterly!$V5 -> 81.86324 | H5: =((G5/B5)^(1/$H$1)-1) -> 0.20271014
A6: Gold | B6: =Quarterly!B6 -> 1 | C6: =Quarterly!$F6 -> 1.182 | D6: =Quarterly!$J6 -> 1.296137 | E6: =Quarterly!$N6 -> 1.559774 | F6: =Quarterly!$R6 -> 2.0347905 | G6: =Quarterly!$V6 -> 4.949544 | H6: =((G6/B6)^(1/$H$1)-1) -> 0.37693373
A7: Alternate | B7: =Quarterly!B7 -> 0 | C7: =Quarterly!$F7 -> 0 | D7: =Quarterly!$J7 -> 0 | E7: =Quarterly!$N7 -> 0 | F7: =Quarterly!$R7 -> 0 | G7: =Quarterly!$V7 -> 0 | H7: 0
A8: Liquid | B8: =Quarterly!B8 -> 4.65 | C8: =Quarterly!$F8 -> 2.8575657 | D8: =Quarterly!$J8 -> 1.5 | E8: =Quarterly!$N8 -> 2 | F8: =Quarterly!$R8 -> 0 | G8: =Quarterly!$V8 -> 0 | H8: =((G8/B8)^(1/$H$1)-1) -> -1
A9: Total | B9: =SUM(B4:B8) -> 84.100595 | C9: =SUM(C4:C8) -> 129.87377 | D9: =SUM(D4:D8) -> 155.92782 | E9: =SUM(E4:E8) -> 230.27305 | F9: =SUM(F4:F8) -> 305.19194 | G9: =SUM(G4:G8) -> 340.00901 | H9: =((G9/B9)^(1/$H$1)-1) -> 0.32232519
A11: CONTRIBUTION
A12: Equity | B12: =B4/B$9 -> 0.54601986 | C12: =C4/C$9 -> 0.65656418 | D12: =D4/D$9 -> 0.66706924 | E12: =E4/E$9 -> 0.7318561 | F12: =F4/F$9 -> 0.76629877 | G12: =G4/G$9 -> 0.74467505
A13: Debt | B13: =B5/B$9 -> 0.38679869 | C13: =C5/C$9 -> 0.31233203 | D13: =D5/D$9 -> 0.31499851 | E13: =E5/E$9 -> 0.25268497 | F13: =F5/F$9 -> 0.22703398 | G13: =G5/G$9 -> 0.24076786
A14: Gold | B14: =B6/B$9 -> 0.011890522 | C14: =C6/C$9 -> 0.0091011446 | D14: =D6/D$9 -> 0.0083124167 | E14: =E6/E$9 -> 0.0067735845 | F14: =F6/F$9 -> 0.0066672485 | G14: =G6/G$9 -> 0.014557097
A15: Alternate | B15: =B7/$B$9 -> 0 | C15: =C7/$B$9 -> 0 | D15: =D7/$B$9 -> 0 | E15: =E7/$B$9 -> 0 | F15: =F7/$B$9 -> 0 | G15: =G7/$B$9 -> 0
A16: Liquid | B16: =B8/B$9 -> 0.055290929 | C16: =C8/C$9 -> 0.022002638 | D16: =D8/D$9 -> 0.0096198357 | E16: =E8/E$9 -> 0.008685341 | F16: =F8/F$9 -> 0 | G16: =G8/G$9 -> 0
A17: Total | B17: =SUM(B12:B16) -> 1 | C17: =SUM(C12:C16) -> 1 | D17: =SUM(D12:D16) -> 1 | E17: =SUM(E12:E16) -> 1 | F17: =SUM(F12:F16) -> 1 | G17: =SUM(G12:G16) -> 1
A19: NEW INVESTMENT
A20: Equity | B20: 0 | C20: =SUM(Quarterly!$C20:$F20) -> 19.892195 | D20: =SUM(Quarterly!$G20:$J20) -> 19.851831 | E20: =SUM(Quarterly!$K20:$N20) -> 23.791935 | F20: =SUM(Quarterly!$O20:$R20) -> 31.473662 | G20: =SUM(Quarterly!$S20:$V20) -> 11.798125 | I20: =SUM(B20:G20) -> 106.80775
A21: Debt | B21: 0 | C21: =SUM(Quarterly!$C21:$F21) -> 4.77074 | D21: =SUM(Quarterly!$G21:$J21) -> 5.37619 | E21: =SUM(Quarterly!$K21:$N21) -> 5.77774 | F21: =SUM(Quarterly!$O21:$R21) -> 6.03276 | G21: =SUM(Quarterly!$S21:$V21) -> 6.8308 | I21: =SUM(B21:G21) -> 28.78823
A22: Gold | B22: 0 | C22: =SUM(Quarterly!$C22:$F22) -> 0.2475 | D22: =SUM(Quarterly!$G22:$J22) -> 0.00516 | E22: =SUM(Quarterly!$K22:$N22) -> 0 | F22: =SUM(Quarterly!$O22:$R22) -> 0 | G22: =SUM(Quarterly!$S22:$V22) -> 1 | I22: =SUM(B22:G22) -> 1.25266
A23: Alternate | B23: 0 | C23: =SUM(Quarterly!$C23:$F23) -> -0.19 | D23: =SUM(Quarterly!$G23:$J23) -> 0 | E23: =SUM(Quarterly!$K23:$N23) -> 0 | F23: =SUM(Quarterly!$O23:$R23) -> 0 | G23: =SUM(Quarterly!$S23:$V23) -> 0 | I23: =SUM(B23:G23) -> -0.19
A24: Liquid | B24: 0 | C24: =SUM(Quarterly!$C24:$F24) -> -1.7924343 | D24: =SUM(Quarterly!$G24:$J24) -> -1.3575657 | E24: =SUM(Quarterly!$K24:$N24) -> 0.5 | F24: =SUM(Quarterly!$O24:$R24) -> -2 | G24: =SUM(Quarterly!$S24:$V24) -> 0 | I24: =SUM(B24:G24) -> -4.65
A25: Total | B25: 0 | C25: =SUM(C20:C24) -> 22.928001 | D25: =SUM(D20:D24) -> 23.875615 | E25: =SUM(E20:E24) -> 30.069675 | F25: =SUM(F20:F24) -> 35.506422 | G25: =SUM(G20:G24) -> 19.628925 | I25: =SUM(B25:G25) -> 132.00864
A27: RETURNS
A28: Equity | B28: 0 | C28: =SUM(Quarterly!$C28:$F28) -> 19.457679 | D28: =SUM(Quarterly!$G28:$J28) -> -1.1076481 | E28: =SUM(Quarterly!$K28:$N28) -> 40.720154 | F28: =SUM(Quarterly!$O28:$R28) -> 33.867808 | G28: =SUM(Quarterly!$S28:$V28) -> 7.5298882 | I28: =SUM(B28:G28) -> 100.46788
A29: Debt | B29: 0 | C29: =SUM(Quarterly!$C29:$F29) -> 3.263 | D29: =SUM(Quarterly!$G29:$J29) -> 3.1771 | E29: =SUM(Quarterly!$K29:$N29) -> 3.29177 | F29: =SUM(Quarterly!$O29:$R29) -> 5.069526 | G29: =SUM(Quarterly!$S29:$V29) -> 5.73255 | I29: =SUM(B29:G29) -> 20.533946
A30: Gold | B30: 0 | C30: =SUM(Quarterly!$C30:$F30) -> -0.0655 | D30: =SUM(Quarterly!$G30:$J30) -> 0.108977 | E30: =SUM(Quarterly!$K30:$N30) -> 0.263637 | F30: =SUM(Quarterly!$O30:$R30) -> 0.4750165 | G30: =SUM(Quarterly!$S30:$V30) -> 1.9147535 | I30: =SUM(B30:G30) -> 2.696884
A31: Alternate | B31: 0 | C31: =SUM(Quarterly!$C31:$F31) -> 0.29485 | D31: =SUM(Quarterly!$G31:$J31) -> 0 | E31: =SUM(Quarterly!$K31:$N31) -> 0 | F31: =SUM(Quarterly!$O31:$R31) -> 0 | G31: =SUM(Quarterly!$S31:$V31) -> 0 | I31: =SUM(B31:G31) -> 0.29485
A32: Liquid | B32: 0 | C32: =SUM(Quarterly!$C32:$F32) -> 0 | D32: =SUM(Quarterly!$G32:$J32) -> 0 | E32: =SUM(Quarterly!$K32:$N32) -> 0 | F32: =SUM(Quarterly!$O32:$R32) -> 0 | G32: =SUM(Quarterly!$S32:$V32) -> 0 | I32: =SUM(B32:G32) -> 0
A33: Total | B33: 0 | C33: =SUM(C28:C32) -> 22.950029 | D33: =SUM(D28:D32) -> 2.1784289 | E33: =SUM(E28:E32) -> 44.275561 | F33: =SUM(F28:F32) -> 39.41235 | G33: =SUM(G28:G32) -> 15.177192 | I33: =SUM(B33:G33) -> 123.99356
A35: NET CHANGE
A36: Equity | B36: =SUMIF(Breakup!$B$58:$L$68,Annual!$A36,Breakup!C$58:C$68) -> 0 | C36: =C20+C28 -> 39.349874 | D36: =D20+D28 -> 18.744182 | E36: =E20+E28 -> 64.512089 | F36: =F20+F28 -> 65.34147 | G36: =G20+G28 -> 19.328013 | I36: =SUM(B36:G36) -> 207.27563
A37: Debt | B37: =SUMIF(Breakup!$B$58:$L$68,Annual!$A37,Breakup!C$58:C$68) -> 0 | C37: =C21+C29 -> 8.03374 | D37: =D21+D29 -> 8.55329 | E37: =E21+E29 -> 9.06951 | F37: =F21+F29 -> 11.102286 | G37: =G21+G29 -> 12.56335 | I37: =SUM(B37:G37) -> 49.322176
A38: Gold | B38: =SUMIF(Breakup!$B$58:$L$68,Annual!$A38,Breakup!C$58:C$68) -> 0 | C38: =C22+C30 -> 0.182 | D38: =D22+D30 -> 0.114137 | E38: =E22+E30 -> 0.263637 | F38: =F22+F30 -> 0.4750165 | G38: =G22+G30 -> 2.9147535 | I38: =SUM(B38:G38) -> 3.949544
A39: Alternate | B39: =SUMIF(Breakup!$B$58:$L$68,Annual!$A39,Breakup!C$58:C$68) -> 0 | C39: =C23+C31 -> 0.10485 | D39: =D23+D31 -> 0 | E39: =E23+E31 -> 0 | F39: =F23+F31 -> 0 | G39: =G23+G31 -> 0 | I39: =SUM(B39:G39) -> 0.10485
A40: Liquid | B40: =SUMIF(Breakup!$B$58:$L$68,Annual!$A40,Breakup!C$58:C$68) -> 0 | C40: =C24+C32 -> -1.7924343 | D40: =D24+D32 -> -1.3575657 | E40: =E24+E32 -> 0.5 | F40: =F24+F32 -> -2 | G40: =G24+G32 -> 0 | I40: =SUM(B40:G40) -> -4.65
A41: Total | B41: =SUM(B36:B40) -> 0 | C41: =C25+C33 -> 45.87803 | D41: =D25+D33 -> 26.054044 | E41: =E25+E33 -> 74.345236 | F41: =F25+F33 -> 74.918772 | G41: =G25+G33 -> 34.806117 | I41: =SUM(B41:G41) -> 256.0022
A42: % Change | C42: =C41/B9 -> 0.54551374 | D42: =D41/C9 -> 0.20061051 | E42: =E41/C9 -> 0.57244225 | F42: =F41/C9 -> 0.57685836 | G42: =G41/D9 -> 0.22321942
A44: % RETURNS
A45: Equity | C45: =C28/B4 -> 0.42372446 | D45: =D28/C4 -> -0.012989821 | E45: =E28/D4 -> 0.39148479 | F45: =F28/D4 -> 0.32560613 | G45: =G28/E4 -> 0.044680673
...

Sheet Quarterly
A1: Quarter | B1: 2020-Q4 | C1: 2021-Q1 | D1: 2021-Q2 | E1: 2021-Q3 | F1: 2021-Q4 | G1: 2022-Q1 | H1: 2022-Q2 | I1: 2022-Q3 | J1: 2022-Q4 | K1: 2023-Q1 | L1: 2023-Q2 | M1: 2023-Q3 | N1: 2023-Q4 | O1: 2024-Q1 | P1: 2024-Q2 | Q1: 2024-Q3 | R1: 2024-Q4 | S1: 2025-Q1 | T1: 2025-Q2 | U1: 2025-Q3 | V1: 2025-Q4 | W1: 2026-Q1 | X1: =COUNTA(B1:W1)-1 -> 21 | Y1: Calendar Quarters
B2: Value (L) | C2: Value (L) | D2: Value (L) | E2: Value (L) | F2: Value (L) | G2: Value (L) | H2: Value (L) | I2: Value (L) | J2: Value (L) | K2: Value (L) | L2: Value (L) | M2: Value (L) | N2: Value (L) | O2: Value (L) | P2: Value (L) | Q2: Value (L) | R2: Value (L) | S2: Value (L) | T2: Value (L) | U2: Value (L) | V2: Value (L) | W2: Value (L) | X2: CAGR | Y2: TOTAL | Z2: Average
A3: NET WORTH
A4: Equity | B4: =Monthly!B4 -> 45.920595 | C4: =Monthly!E4 -> 55.636562 | D4: =Monthly!H4 -> 64.627927 | E4: =Monthly!K4 -> 78.201752 | F4: =Monthly!N4 -> 85.270469 | G4: =Monthly!Q4 -> 88.963405 | H4: =Monthly!T4 -> 82.702511 | I4: =Monthly!$W4 -> 96.137323 | J4: =Monthly!$Z4 -> 104.01465 | K4: =Monthly!$AC4 -> 108.818 | L4: =Monthly!$AF4 -> 131.07883 | M4: =Monthly!$AI4 -> 147.99221 | N4: =Monthly!$AL4 -> 168.52674 | O4: =Monthly!$AO4 -> 188.05701 | P4: =Monthly!$AR4 -> 212.83646 | Q4: =Monthly!$AU4 -> 237.05244 | R4: =Monthly!$AX4 -> 233.86821 | S4: =Monthly!$BA4 -> 207.93476 | T4: =Monthly!$BD4 -> 243.49772 | U4: =Monthly!$BG4 -> 242.45864 | V4: =Monthly!$BJ4 -> 253.19622 | W4: =Monthly!$BM4 -> 226.98142 | X4: =((W4/B4)^(4/$X$1)-1) -> 0.35577368
A5: Debt | B5: =Monthly!B5 -> 32.53 | C5: =Monthly!E5 -> 36.019 | D5: =Monthly!H5 -> 37.34856 | E5: =Monthly!K5 -> 39.71884 | F5: =Monthly!N5 -> 40.56374 | G5: =Monthly!Q5 -> 44.31114 | H5: =Monthly!T5 -> 45.29654 | I5: =Monthly!$W5 -> 47.860834 | J5: =Monthly!$Z5 -> 49.11703 | K5: =Monthly!$AC5 -> 53.19227 | L5: =Monthly!$AF5 -> 54.226046 | M5: =Monthly!$AI5 -> 57.09389 | N5: =Monthly!$AL5 -> 58.18654 | O5: =Monthly!$AO5 -> 64.072264 | P5: =Monthly!$AR5 -> 65.21269 | Q5: =Monthly!$AU5 -> 68.03128 | R5: =Monthly!$AX5 -> 69.28894 | S5: =Monthly!$BA5 -> 77.71356 | T5: =Monthly!$BD5 -> 78.99227 | U5: =Monthly!$BG5 -> 80.222692 | V5: =Monthly!$BJ5 -> 81.86324 | W5: =Monthly!$BM5 -> 88.6149 | X5: =((W5/B5)^(4/$X$1)-1) -> 0.21031819
A6: Gold | B6: =Monthly!B6 -> 1 | C6: =Monthly!E6 -> 1.1650255 | D6: =Monthly!H6 -> 1.1951 | E6: =Monthly!K6 -> 1.17335 | F6: =Monthly!N6 -> 1.182 | G6: =Monthly!Q6 -> 1.18455 | H6: =Monthly!T6 -> 1.211 | I6: =Monthly!$W6 -> 1.2162 | J6: =Monthly!$Z6 -> 1.296137 | K6: =Monthly!$AC6 -> 1.382417 | L6: =Monthly!$AF6 -> 1.473594 | M6: =Monthly!$AI6 -> 1.468757 | N6: =Monthly!$AL6 -> 1.559774 | O6: =Monthly!$AO6 -> 1.676741 | P6: =Monthly!$AR6 -> 1.86114 | Q6: =Monthly!$AU6 -> 1.983838 | R6: =Monthly!$AX6 -> 2.0347905 | S6: =Monthly!$BA6 -> 2.190049 | T6: =Monthly!$BD6 -> 2.447904 | U6: =Monthly!$BG6 -> 4.3079155 | V6: =Monthly!$BJ6 -> 4.949544 | W6: =Monthly!$BM6 -> 5.054594 | X6: =((W6/B6)^(4/$X$1)-1) -> 0.36155592
A7: Alternate | B7: =Monthly!B7 -> 0 | C7: =Monthly!E7 -> 0 | D7: =Monthly!H7 -> 0 | E7: =Monthly!K7 -> 0.54 | F7: =Monthly!N7 -> 0 | G7: =Monthly!Q7 -> 0 | H7: =Monthly!T7 -> 0 | I7: =Monthly!$W7 -> 0 | J7: =Monthly!$Z7 -> 0 | K7: =Monthly!$AC7 -> 0 | L7: =Monthly!$AF7 -> 0 | M7: =Monthly!$AI7 -> 0 | N7: =Monthly!$AL7 -> 0 | O7: =Monthly!$AO7 -> 0 | P7: =Monthly!$AR7 -> 0 | Q7: =Monthly!$AU7 -> 0 | R7: =Monthly!$AX7 -> 0 | S7: =Monthly!$BA7 -> 0 | T7: =Monthly!$BD7 -> 0 | U7: =Monthly!$BG7 -> 0 | V7: =Monthly!$BJ7 -> 0 | W7: =Monthly!$BM7 -> 0 | X7: -
A8: Liquid | B8: =Monthly!B8 -> 4.65 | C8: =Monthly!E8 -> 1.0035016 | D8: =Monthly!H8 -> 3.5291139 | E8: =Monthly!K8 -> 4.3487874 | F8: =Monthly!N8 -> 2.8575657 | G8: =Monthly!Q8 -> 1.347861 | H8: =Monthly!T8 -> 0 | I8: =Monthly!$W8 -> 2.5 | J8: =Monthly!$Z8 -> 1.5 | K8: =Monthly!$AC8 -> 3 | L8: =Monthly!$AF8 -> 0 | M8: =Monthly!$AI8 -> 0 | N8: =Monthly!$AL8 -> 2 | O8: =Monthly!$AO8 -> 2.0134634 | P8: =Monthly!$AR8 -> 0 | Q8: =Monthly!$AU8 -> 3.0407111 | R8: =Monthly!$AX8 -> 0 | S8: =Monthly!$BA8 -> 9 | T8: =Monthly!$BD8 -> 0 | U8: =Monthly!$BG8 -> 0 | V8: =Monthly!$BJ8 -> 0 | W8: =Monthly!$BM8 -> 0
A9: Total | B9: =SUM(B4:B8) -> 84.100595 | C9: =SUM(C4:C8) -> 93.824089 | D9: =SUM(D4:D8) -> 106.7007 | E9: =SUM(E4:E8) -> 123.98273 | F9: =SUM(F4:F8) -> 129.87377 | G9: =SUM(G4:G8) -> 135.80696 | H9: =SUM(H4:H8) -> 129.21005 | I9: =SUM(I4:I8) -> 147.71436 | ... W9: =SUM(W4:W8) -> 320.65091 | X9: =((W9/B9)^(4/$X$1)-1) -> 0.2903607
A11: CONTRIBUTION
A12: Equity | B12: =B4/B$9 -> 0.54601986 | C12: =C4/C$9 -> 0.59298803 | D12: =D4/D$9 -> 0.60569356 | E12: =E4/E$9 -> 0.63074714 | F12: =F4/F$9 -> 0.65656418 | G12: =G4/G$9 -> 0.65507252 | H12: =H4/H$9 -> 0.64006252 | I12: =I4/I$9 -> 0.65083263 | ... W12: =W4/W$9 -> 0.70787704
A13: Debt | B13: =B5/B$9 -> 0.38679869 | C13: =C5/C$9 -> 0.38389928 | D13: =D5/D$9 -> 0.35003106 | E13: =E5/E$9 -> 0.32035784 | F13: =F5/F$9 -> 0.31233203 | G13: =G5/G$9 -> 0.32628034 | H13: =H5/H$9 -> 0.35056514 | I13: =I5/I$9 -> 0.32400936 | ... W13: =W5/W$9 -> 0.27635942
A14: Gold | B14: =B6/B$9 -> 0.011890522 | C14: =C6/C$9 -> 0.012417126 | D14: =D6/D$9 -> 0.011200489 | E14: =E6/E$9 -> 0.0094638181 | F14: =F6/F$9 -> 0.0091011446 | G14: =G6/G$9 -> 0.0087223073 | H14: =H6/H$9 -> 0.0093723359 | I14: =I6/I$9 -> 0.0082334583 | ... W14: =W6/W$9 -> 0.015763542
A15: Alternate | B15: =B7/$B$9 -> 0 | C15: =C7/$B$9 -> 0 | D15: =D7/$B$9 -> 0 | E15: =E7/$B$9 -> 0.0064208821 | F15: =F7/$B$9 -> 0 | G15: =G7/$B$9 -> 0 | H15: =H7/$B$9 -> 0 | I15: =I7/$B$9 -> 0 | ... K15: =K7/$B$9 -> 0 | L15: =L7/L$9 -> 0 | M15: =M7/M$9 -> 0 | N15: =N7/N$9 -> 0 | O15: =O7/O$9 -> 0 | P15: =P7/P$9 -> 0 | Q15: =Q7/Q$9 -> 0 | R15: =R7/R$9 -> 0 | S15: =S7/S$9 -> 0 | ... W15: =W7/W$9 -> 0
A16: Liquid | B16: =B8/B$9 -> 0.055290929 | C16: =C8/C$9 -> 0.010695565 | D16: =D8/D$9 -> 0.033074889 | E16: =E8/E$9 -> 0.035075752 | F16: =F8/F$9 -> 0.022002638 | G16: =G8/G$9 -> 0.0099248304 | H16: =H8/H$9 -> 0 | I16: =I8/I$9 -> 0.016924557 | ... W16: =W8/W$9 -> 0
A17: Total | B17: =SUM(B12:B16) -> 1 | C17: =SUM(C12:C16) -> 1 | D17: =SUM(D12:D16) -> 1 | E17: =SUM(E12:E16) -> 1.0020654 | F17: =SUM(F12:F16) -> 1 | G17: =SUM(G12:G16) -> 1 | H17: =SUM(H12:H16) -> 1 | I17: =SUM(I12:I16) -> 1 | ... W17: =SUM(W12:W16) -> 1
A19: NEW INVESTMENT
A20: Equity | B20: 0 | C20: =Monthly!C20+Monthly!D20+Monthly!E20 -> 4.2563708 | D20: =Monthly!F20+Monthly!G20+Monthly!H20 -> 2.6 | E20: =Monthly!K20+Monthly!I20+Monthly!J20 -> 6.1903996 | F20: =Monthly!M20+Monthly!L20+Monthly!N20 -> 6.8454247 | G20: =Monthly!Q20+Monthly!O20+Monthly!P20 -> 5.4704209 | H20: =Monthly!T20+Monthly!R20+Monthly!S20 -> 1.9750152 | I20: =Monthly!$W20+Monthly!$U20+Monthly!$V20 -> 4.9833422 | J20: =Monthly!$X20+Monthly!$Y20+Monthly!$Z20 -> 7.4230522 | K20: =Monthly!$AA20+Monthly!$AB20+Monthly!$AC20 -> 7.1736018 | L20: =Monthly!$AD20+Monthly!$AE20+Monthly!$AF20 -> 5.9398419 | M20: =Monthly!$AG20+Monthly!$AH20+Monthly!$AI20 -> 8.2797045 | N20: =Monthly!$AJ20+Monthly!$AK20+Monthly!$AL20 -> 2.3987867 | O20: =Monthly!$AM20+Monthly!$AN20+Monthly!$AO20 -> 8.2010547 | P20: =Monthly!$AP20+Monthly!$AQ20+Monthly!$AR20 -> 6.4789379 | Q20: =Monthly!$AS20+Monthly!$AT20+Monthly!$AU20 -> 8.516083 | R20: =Monthly!$AV20+Monthly!$AW20+Monthly!$AX20 -> 8.2775865 | S20: =Monthly!$AY20+Monthly!$AZ20+Monthly!$BA20 -> -3.2658037 | T20: =Monthly!$BB20+Monthly!$BC20+Monthly!$BD20 -> 8.6095711 | U20: =Monthly!$BE20+Monthly!$BF20+Monthly!$BG20 -> 1.4188489 | V20: =Monthly!$BH20+Monthly!$BI20+Monthly!$BJ20 -> 5.0355088 | W20: =SUM(Monthly!$BK20:$BM20) -> 2.5816775 | Y20: =SUM(B20:W20) -> 109.38943 | Z20: =Y20/$X$1 -> 5.2090203
A21: Debt | B21: 0 | C21: =Monthly!C21+Monthly!D21+Monthly!E21 -> 0.9 | D21: =Monthly!F21+Monthly!G21+Monthly!H21 -> 0.69596 | E21: =Monthly!K21+Monthly!I21+Monthly!J21 -> 2.34888 | F21: =Monthly!M21+Monthly!L21+Monthly!N21 -> 0.8259 | G21: =Monthly!Q21+Monthly!O21+Monthly!P21 -> 0.8364 | H21: =Monthly!T21+Monthly!R21+Monthly!S21 -> 0.8259 | I21: =Monthly!$W21+Monthly!$U21+Monthly!$V21 -> 2.495294 | J21: =Monthly!$X21+Monthly!$Y21+Monthly!$Z21 -> 1.218596 | K21: =Monthly!$AA21+Monthly!$AB21+Monthly!$AC21 -> 0.937 | L21: =Monthly!$AD21+Monthly!$AE21+Monthly!$AF21 -> 0.9555 | M21: =Monthly!$AG21+Monthly!$AH21+Monthly!$AI21 -> 2.8305 | N21: =Monthly!$AJ21+Monthly!$AK21+Monthly!$AL21 -> 1.05474 | O21: =Monthly!$AM21+Monthly!$AN21+Monthly!$AO21 -> 1.05474 | P21: =Monthly!$AP21+Monthly!$AQ21+Monthly!$AR21 -> 1.05474 | Q21: =Monthly!$AS21+Monthly!$AT21+Monthly!$AU21 -> 2.70474 | R21: =Monthly!$AV21+Monthly!$AW21+Monthly!$AX21 -> 1.21854 | S21: =Monthly!$AY21+Monthly!$AZ21+Monthly!$BA21 -> 2.71854 | T21: =Monthly!$BB21+Monthly!$BC21+Monthly!$BD21 -> 1.21854 | U21: =Monthly!$BE21+Monthly!$BF21+Monthly!$BG21 -> 1.21854 | V21: =Monthly!$BH21+Monthly!$BI21+Monthly!$BJ21 -> 1.67518 | W21: =SUM(Monthly!$BK21:$BM21) -> 1.42518 | Y21: =SUM(B21:W21) -> 30.21341 | Z21: =Y21/$X$1 -> 1.4387338
A22: Gold | B22: 0 | C22: =Monthly!C22+Monthly!D22+Monthly!E22 -> 0.2475 | D22: =Monthly!F22+Monthly!G22+Monthly!H22 -> 0 | E22: =Monthly!K22+Monthly!I22+Monthly!J22 -> 0 | F22: =Monthly!M22+Monthly!L22+Monthly!N22 -> 0 | G22: =Monthly!Q22+Monthly!O22+Monthly!P22 -> -0.0197 | H22: =Monthly!T22+Monthly!R22+Monthly!S22 -> 0.02645 | I22: =Monthly!$W22+Monthly!$U22+Monthly!$V22 -> -0.00159 | J22: =Monthly!$X22+Monthly!$Y22+Monthly!$Z22 -> 0 | K22: =Monthly!$AA22+Monthly!$AB22+Monthly!$AC22 -> 0 | L22: =Monthly!$AD22+Monthly!$AE22+Monthly!$AF22 -> 0 | M22: =Monthly!$AG22+Monthly!$AH22+Monthly!$AI22 -> 0 | N22: =Monthly!$AJ22+Monthly!$AK22+Monthly!$AL22 -> 0 | O22: =Monthly!$AM22+Monthly!$AN22+Monthly!$AO22 -> 0 | P22: =Monthly!$AP22+Monthly!$AQ22+Monthly!$AR22 -> 0 | Q22: =Monthly!$AS22+Monthly!$AT22+Monthly!$AU22 -> 0 | R22: =Monthly!$AV22+Monthly!$AW22+Monthly!$AX22 -> 0 | S22: =Monthly!$AY22+Monthly!$AZ22+Monthly!$BA22 -> 0 | T22: =Monthly!$BB22+Monthly!$BC22+Monthly!$BD22 -> 0 | U22: =Monthly!$BE22+Monthly!$BF22+Monthly!$BG22 -> 1 | V22: =Monthly!$BH22+Monthly!$BI22+Monthly!$BJ22 -> 0 | W22: =SUM(Monthly!$BK22:$BM22) -> 0 | Y22: =SUM(B22:W22) -> 1.25266 | Z22: =Y22/$X$1 -> 0.059650476
A23: Alternate | B23: 0 | C23: =Monthly!C23+Monthly!D23+Monthly!E23 -> 0 | D23: =Monthly!F23+Monthly!G23+Monthly!H23 -> 0 | E23: =Monthly!K23+Monthly!I23+Monthly!J23 -> 0.54 | F23: =Monthly!M23+Monthly!L23+Monthly!N23 -> -0.73 | G23: =Monthly!Q23+Monthly!O23+Monthly!P23 -> 0 | H23: =Monthly!T23+Monthly!R23+Monthly!S23 -> 0 | I23: =Monthly!$W23+Monthly!$U23+Monthly!$V23 -> 0 | J23: =Monthly!$X23+Monthly!$Y23+Monthly!$Z23 -> 0 | K23: =Monthly!$AA23+Monthly!$AB23+Monthly!$AC23 -> 0 | L23: =Monthly!$AD23+Monthly!$AE23+Monthly!$AF23 -> 0 | M23: =Monthly!$AG23+Monthly!$AH23+Monthly!$AI23 -> 0 | N23: =Monthly!$AJ23+Monthly!$AK23+Monthly!$AL23 -> 0 | O23: =Monthly!$AM23+Monthly!$AN23+Monthly!$AO23 -> 0 | P23: =Monthly!$AP23+Monthly!$AQ23+Monthly!$AR23 -> 0 | Q23: =Monthly!$AS23+Monthly!$AT23+Monthly!$AU23 -> 0 | R23: =Monthly!$AV23+Monthly!$AW23+Monthly!$AX23 -> 0 | S23: =Monthly!$AY23+Monthly!$AZ23+Monthly!$BA23 -> 0 | T23: =Monthly!$BB23+Monthly!$BC23+Monthly!$BD23 -> 0 | U23: =Monthly!$BE23+Monthly!$BF23+Monthly!$BG23 -> 0 | V23: =Monthly!$BH23+Monthly!$BI23+Monthly!$BJ23 -> 0 | W23: =SUM(Monthly!$BK23:$BM23) -> 0 | Y23: =SUM(B23:W23) -> -0.19 | Z23: =Y23/$X$1 -> -0.009047619
A24: Liquid | B24: 0 | C24: =Monthly!C24+Monthly!D24+Monthly!E24 -> -3.6464984 | D24: =Monthly!F24+Monthly!G24+Monthly!H24 -> 2.5256122 | E24: =Monthly!K24+Monthly!I24+Monthly!J24 -> 0.81967358 | F24: =Monthly!M24+Monthly!L24+Monthly!N24 -> -1.4912217 | G24: =Monthly!Q24+Monthly!O24+Monthly!P24 -> -1.5097047 | H24: =Monthly!T24+Monthly!R24+Monthly!S24 -> -1.347861 | I24: =Monthly!$W24+Monthly!$U24+Monthly!$V24 -> 2.5 | J24: =Monthly!$X24+Monthly!$Y24+Monthly!$Z24 -> -1 | K24: =Monthly!$AA24+Monthly!$AB24+Monthly!$AC24 -> 1.5 | L24: =Monthly!$AD24+Monthly!$AE24+Monthly!$AF24 -> -3 | M24: =Monthly!$AG24+Monthly!$AH24+Monthly!$AI24 -> 0 | N24: =Monthly!$AJ24+Monthly!$AK24+Monthly!$AL24 -> 2 | O24: =Monthly!$AM24+Monthly!$AN24+Monthly!$AO24 -> 0.013463446 | P24: =Monthly!$AP24+Monthly!$AQ24+Monthly!$AR24 -> -2.0134634 | Q24: =Monthly!$AS24+Monthly!$AT24+Monthly!$AU24 -> 3.0407111 | R24: =Monthly!$AV24+Monthly!$AW24+Monthly!$AX24 -> -3.0407111 | S24: =Monthly!$AY24+Monthly!$AZ24+Monthly!$BA24 -> 9 | T24: =Monthly!$BB24+Monthly!$BC24+Monthly!$BD24 -> -9 | U24: =Monthly!$BE24+Monthly!$BF24+Monthly!$BG24 -> 0 | V24: =Monthly!$BH24+Monthly!$BI24+Monthly!$BJ24 -> 0 | W24: =SUM(Monthly!$BK24:$BM24) -> 0 | Y24: =SUM(B24:W24) -> -4.65 | Z24: =Y24/$X$1 -> -0.22142857
A25: Total | B25: =SUM(B20:B24) -> 0 | C25: =SUM(C20:C24) -> 1.7573724 | D25: =SUM(D20:D24) -> 5.8215722 | E25: =SUM(E20:E24) -> 9.8989531 | F25: =SUM(F20:F24) -> 5.4501029 | G25: =SUM(G20:G24) -> 4.7774162 | H25: =SUM(H20:H24) -> 1.4795042 | I25: =SUM(I20:I24) -> 9.9770462 | ... W25: =SUM(W20:W24) -> 4.0068575 | Y25: =SUM(B25:W25) -> 136.0155 | Z25: =Y25/$X$1 -> 6.4769283
A27: RETURNS
A28: Equity | B28: 0 | C28: =Monthly!C28+Monthly!D28+Monthly!E28 -> 5.459596 | D28: =Monthly!F28+Monthly!G28+Monthly!H28 -> 6.3913656 | E28: =Monthly!K28+Monthly!I28+Monthly!J28 -> 7.3834255 | F28: =Monthly!M28+Monthly!L28+Monthly!N28 -> 0.2232921 | G28: =Monthly!Q28+Monthly!O28+Monthly!P28 -> -1.7774849 | H28: =Monthly!T28+Monthly!R28+Monthly!S28 -> -8.2359098 | I28: =Monthly!$W28+Monthly!$U28+Monthly!$V28 -> 8.4514702 | J28: =Monthly!$X28+Monthly!$Y28+Monthly!$Z28 -> 0.45427629 | K28: =Monthly!$AA28+Monthly!$AB28+Monthly!$AC28 -> -2.3702547 | L28: =Monthly!$AD28+Monthly!$AE28+Monthly!$AF28 -> 16.32099 | M28: =Monthly!$AG28+Monthly!$AH28+Monthly!$AI28 -> 8.6336759 | N28: =Monthly!$AJ28+Monthly!$AK28+Monthly!$AL28 -> 18.135743 | O28: =Monthly!$AM28+Monthly!$AN28+Monthly!$AO28 -> 11.329213 | P28: =Monthly!$AP28+Monthly!$AQ28+Monthly!$AR28 -> 18.300515 | Q28: =Monthly!$AS28+Monthly!$AT28+Monthly!$AU28 -> 15.699895 | R28: =Monthly!$AV28+Monthly!$AW28+Monthly!$AX28 -> -11.461816 | S28: =Monthly!$AY28+Monthly!$AZ28+Monthly!$BA28 -> -22.66765 | T28: =Monthly!$BB28+Monthly!$BC28+Monthly!$BD28 -> 26.953391 | U28: =Monthly!$BE28+Monthly!$BF28+Monthly!$BG28 -> -2.4579275 | V28: =Monthly!$BH28+Monthly!$BI28+Monthly!$BJ28 -> 5.7020745 | W28: =SUM(Monthly!$BK28:$BM28) -> -28.796484 | Y28: =SUM(B28:W28) -> 71.671397 | Z28: =Y28/$X$1 -> 3.4129237
A29: Debt | B29: 0 | C29: =Monthly!C29+Monthly!D29+Monthly!E29 -> 2.589 | D29: =Monthly!F29+Monthly!G29+Monthly!H29 -> 0.6336 | E29: =Monthly!K29+Monthly!I29+Monthly!J29 -> 0.0214 | F29: =Monthly!M29+Monthly!L29+Monthly!N29 -> 0.019 | G29: =Monthly!Q29+Monthly!O29+Monthly!P29 -> 2.911 | H29: =Monthly!T29+Monthly!R29+Monthly!S29 -> 0.1595 | I29: =Monthly!$W29+Monthly!$U29+Monthly!$V29 -> 0.069 | J29: =Monthly!$X29+Monthly!$Y29+Monthly!$Z29 -> 0.0376 | K29: =Monthly!$AA29+Monthly!$AB29+Monthly!$AC29 -> 3.13824 | L29: =Monthly!$AD29+Monthly!$AE29+Monthly!$AF29 -> 0.078276 | M29: =Monthly!$AG29+Monthly!$AH29+Monthly!$AI29 -> 0.037344 | N29: =Monthly!$AJ29+Monthly!$AK29+Monthly!$AL29 -> 0.03791 | O29: =Monthly!$AM29+Monthly!$AN29+Monthly!$AO29 -> 4.830984 | P29: =Monthly!$AP29+Monthly!$AQ29+Monthly!$AR29 -> 0.087476 | Q29: =Monthly!$AS29+Monthly!$AT29+Monthly!$AU29 -> 0.111946 | R29: =Monthly!$AV29+Monthly!$AW29+Monthly!$AX29 -> 0.03912 | S29: =Monthly!$AY29+Monthly!$AZ29+Monthly!$BA29 -> 5.70608 | T29: =Monthly!$BB29+Monthly!$BC29+Monthly!$BD29 -> 0.060122 | U29: =Monthly!$BE29+Monthly!$BF29+Monthly!$BG29 -> 0.02373 | V29: =Monthly!$BH29+Monthly!$BI29+Monthly!$BJ29 -> -0.057382 | W29: =SUM(Monthly!$BK29:$BM29) -> 5.33513 | Y29: =SUM(B29:W29) -> 25.869076 | Z29: =Y29/$X$1 -> 1.2318608
A30: Gold | B30: 0 | C30: =Monthly!C30+Monthly!D30+Monthly!E30 -> -0.0824745 | D30: =Monthly!F30+Monthly!G30+Monthly!H30 -> 0.0300745 | E30: =Monthly!K30+Monthly!I30+Monthly!J30 -> -0.02175 | F30: =Monthly!M30+Monthly!L30+Monthly!N30 -> 0.00865 | G30: =Monthly!Q30+Monthly!O30+Monthly!P30 -> 0.02225 | H30: =Monthly!T30+Monthly!R30+Monthly!S30 -> 0 | I30: =Monthly!$W30+Monthly!$U30+Monthly!$V30 -> 0.00679 | J30: =Monthly!$X30+Monthly!$Y30+Monthly!$Z30 -> 0.079937 | K30: =Monthly!$AA30+Monthly!$AB30+Monthly!$AC30 -> 0.08628 | L30: =Monthly!$AD30+Monthly!$AE30+Monthly!$AF30 -> 0.091177 | M30: =Monthly!$AG30+Monthly!$AH30+Monthly!$AI30 -> -0.004837 | N30: =Monthly!$AJ30+Monthly!$AK30+Monthly!$AL30 -> 0.091017 | O30: =Monthly!$AM30+Monthly!$AN30+Monthly!$AO30 -> 0.116967 | P30: =Monthly!$AP30+Monthly!$AQ30+Monthly!$AR30 -> 0.184399 | Q30: =Monthly!$AS30+Monthly!$AT30+Monthly!$AU30 -> 0.122698 | R30: =Monthly!$AV30+Monthly!$AW30+Monthly!$AX30 -> 0.0509525 | S30: =Monthly!$AY30+Monthly!$AZ30+Monthly!$BA30 -> 0.1552585 | T30: =Monthly!$BB30+Monthly!$BC30+Monthly!$BD30 -> 0.257855 | U30: =Monthly!$BE30+Monthly!$BF30+Monthly!$BG30 -> 0.8600115 | V30: =Monthly!$BH30+Monthly!$BI30+Monthly!$BJ30 -> 0.6416285 | W30: =SUM(Monthly!$BK30:$BM30) -> 0.10505 | Y30: =SUM(B30:W30) -> 2.801934 | Z30: =Y30/$X$1 -> 0.13342543
A31: Alternate | B31: 0 | C31: =Monthly!C31+Monthly!D31+Monthly!E31 -> 0 | D31: =Monthly!F31+Monthly!G31+Monthly!H31 -> 0 | E31: =Monthly!K31+Monthly!I31+Monthly!J31 -> 0.10485 | F31: =Monthly!M31+Monthly!L31+Monthly!N31 -> 0.19 | G31: =Monthly!Q31+Monthly!O31+Monthly!P31 -> 0 | H31: =Monthly!T31+Monthly!R31+Monthly!S31 -> 0 | I31: =Monthly!$W31+Monthly!$U31+Monthly!$V31 -> 0 | J31: =Monthly!$X31+Monthly!$Y31+Monthly!$Z31 -> 0 | K31: =Monthly!$AA31+Monthly!$AB31+Monthly!$AC31 -> 0 | L31: =Monthly!$AD31+Monthly!$AE31+Monthly!$AF31 -> 0 | M31: =Monthly!$AG31+Monthly!$AH31+Monthly!$AI31 -> 0 | N31: =Monthly!$AJ31+Monthly!$AK31+Monthly!$AL31 -> 0 | O31: =Monthly!$AM31+Monthly!$AN31+Monthly!$AO31 -> 0 | P31: =Monthly!$AP31+Monthly!$AQ31+Monthly!$AR31 -> 0 | Q31: =Monthly!$AS31+Monthly!$AT31+Monthly!$AU31 -> 0 | R31: =Monthly!$AV31+Monthly!$AW31+Monthly!$AX31 -> 0 | S31: =Monthly!$AY31+Monthly!$AZ31+Monthly!$BA31 -> 0 | T31: =Monthly!$BB31+Monthly!$BC31+Monthly!$BD31 -> 0 | U31: =Monthly!$BE31+Monthly!$BF31+Monthly!$BG31 -> 0 | V31: =Monthly!$BH31+Monthly!$BI31+Monthly!$BJ31 -> 0 | W31: =SUM(Monthly!$BK31:$BM31) -> 0 | Y31: =SUM(B31:W31) -> 0.29485 | Z31: =Y31/$X$1 -> 0.014040476
A32: Liquid | B32: 0 | C32: =Monthly!C32+Monthly!D32+Monthly!E32 -> 0 | D32: =Monthly!F32+Monthly!G32+Monthly!H32 -> 0 | E32: =Monthly!K32+Monthly!I32+Monthly!J32 -> 0 | F32: =Monthly!M32+Monthly!L32+Monthly!N32 -> 0 | G32: =Monthly!Q32+Monthly!O32+Monthly!P32 -> 0 | H32: =Monthly!T32+Monthly!R32+Monthly!S32 -> 0 | I32: =Monthly!$W32+Monthly!$U32+Monthly!$V32 -> 0 | J32: =Monthly!$X32+Monthly!$Y32+Monthly!$Z32 -> 0 | K32: =Monthly!$AA32+Monthly!$AB32+Monthly!$AC32 -> 0 | L32: =Monthly!$AD32+Monthly!$AE32+Monthly!$AF32 -> 0 | M32: =Monthly!$AG32+Monthly!$AH32+Monthly!$AI32 -> 0 | N32: =Monthly!$AJ32+Monthly!$AK32+Monthly!$AL32 -> 0 | O32: =Monthly!$AM32+Monthly!$AN32+Monthly!$AO32 -> 0 | P32: =Monthly!$AP32+Monthly!$AQ32+Monthly!$AR32 -> 0 | Q32: =Monthly!$AS32+Monthly!$AT32+Monthly!$AU32 -> 0 | R32: =Monthly!$AV32+Monthly!$AW32+Monthly!$AX32 -> 0 | S32: =Monthly!$AY32+Monthly!$AZ32+Monthly!$BA32 -> 0 | T32: =Monthly!$BB32+Monthly!$BC32+Monthly!$BD32 -> 0 | U32: =Monthly!$BE32+Monthly!$BF32+Monthly!$BG32 -> 0 | V32: =Monthly!$BH32+Monthly!$BI32+Monthly!$BJ32 -> 0 | W32: =SUM(Monthly!$BK32:$BM32) -> 0 | Y32: =SUM(B32:W32) -> 0 | Z32: =Y32/$X$1 -> 0
A33: Total | B33: =SUM(B28:B32) -> 0 | C33: =SUM(C28:C32) -> 7.9661215 | D33: =SUM(D28:D32) -> 7.0550401 | E33: =SUM(E28:E32) -> 7.4879255 | F33: =SUM(F28:F32) -> 0.4409421 | G33: =SUM(G28:G32) -> 1.1557651 | H33: =SUM(H28:H32) -> -8.0764098 | I33: =SUM(I28:I32) -> 8.5272602 | ... W33: =SUM(W28:W32) -> -23.356304 | Y33: =SUM(B33:W33) -> 100.63726 | Z33: =Y33/$X$1 -> 4.7922503
A35: NET CHANGE
A36: Equity | B36: =SUMIF(Breakup!$B$58:$L$68,Quarterly!$A36,Breakup!C$58:C$68) -> 0 | C36: =C20+C28 -> 9.7159668 | D36: =D20+D28 -> 8.9913656 | E36: =E20+E28 -> 13.573825 | F36: =F20+F28 -> 7.0687168 | G36: =G20+G28 -> 3.692936 | H36: =H20+H28 -> -6.2608945 | I36: =I20+I28 -> 13.434812 | J36: =J20+J28 -> 7.8773285 | ... W36: =W20+W28 -> -26.214806 | Y36: =SUM(B36:W36) -> 181.06082 | Z36: =Y36/$X$1 -> 8.6219439
A37: Debt | B37: =SUMIF(Breakup!$B$58:$L$68,Quarterly!$A37,Breakup!C$58:C$68) -> 0 | C37: =C21+C29 -> 3.489 | D37: =D21+D29 -> 1.32956 | E37: =E21+E29 -> 2.37028 | F37: =F21+F29 -> 0.8449 | G37: =G21+G29 -> 3.7474 | H37: =H21+H29 -> 0.9854 | I37: =I21+I29 -> 2.564294 | J37: =J21+J29 -> 1.256196 | ... W37: =W21+W29 -> 6.76031 | Y37: =SUM(B37:W37) -> 56.082486 | Z37: =Y37/$X$1 -> 2.6705946
A38: Gold | B38: =SUMIF(Breakup!$B$58:$L$68,Quarterly!$A38,Breakup!C$58:C$68) -> 0 | C38: =C22+C30 -> 0.1650255 | D38: =D22+D30 -> 0.0300745 | E38: =E22+E30 -> -0.02175 | F38: =F22+F30 -> 0.00865 | G38: =G22+G30 -> 0.00255 | H38: =H22+H30 -> 0.02645 | I38: =I22+I30 -> 0.0052 | J38: =J22+J30 -> 0.079937 | ... W38: =W22+W30 -> 0.10505 | Y38: =SUM(B38:W38) -> 4.054594 | Z38: =Y38/$X$1 -> 0.1930759
A39: Alternate | B39: =SUMIF(Breakup!$B$58:$L$68,Quarterly!$A39,Breakup!C$58:C$68) -> 0 | C39: =C23+C31 -> 0 | D39: =D23+D31 -> 0 | E39: =E23+E31 -> 0.64485 | F39: =F23+F31 -> -0.54 | G39: =G23+G31 -> 0 | H39: =H23+H31 -> 0 | I39: =I23+I31 -> 0 | J39: =J23+J31 -> 0 | ... W39: =W23+W31 -> 0 | Y39: =SUM(B39:W39) -> 0.10485 | Z39: =Y39/$X$1 -> 0.0049928571
A40: Liquid | B40: =SUMIF(Breakup!$B$58:$L$68,Quarterly!$A40,Breakup!C$58:C$68) -> 0 | C40: =C24+C32 -> -3.6464984 | D40: =D24+D32 -> 2.5256122 | E40: =E24+E32 -> 0.81967358 | F40: =F24+F32 -> -1.4912217 | G40: =G24+G32 -> -1.5097047 | H40: =H24+H32 -> -1.347861 | I40: =I24+I32 -> 2.5 | J40: =J24+J32 -> -1 | ... W40: =W24+W32 -> 0 | Y40: =SUM(B40:W40) -> -4.65 | Z40: =Y40/$X$1 -> -0.22142857
A41: Total | B41: =SUM(B36:B40) -> 0 | C41: =C25+C33 -> 9.7234939 | D41: =D25+D33 -> 12.876612 | E41: =E25+E33 -> 17.386879 | F41: =F25+F33 -> 5.891045 | G41: =G25+G33 -> 5.9331813 | H41: =H25+H33 -> -6.5969055 | I41: =I25+I33 -> 18.504306 | J41: =J25+J33 -> 8.2134615 | ... W41: =W25+W33 -> -19.349446 | Y41: =SUM(B41:W41) -> 236.65275 | Z41: =Y41/$X$1 -> 11.269179
A42: % Change | C42: =C41/B9 -> 0.11561742 | D42: =D41/C9 -> 0.13724207 | E42: =E41/D9 -> 0.16294999 | F42: =F41/E9 -> 0.047515045 | G42: =G41/F9 -> 0.045684214 | H42: =H41/G9 -> -0.048575608 | I42: =I41/H9 -> 0.14321104 | J42: =J41/I9 -> 0.055603678 | ... W42: =W41/V9 -> -0.056908629
A44: % RETURNS
A45: Equity | C45: =C28/(B4) -> 0.1188921 | D45: =D28/(C4) -> 0.11487708 | E45: =E28/(D4) -> 0.11424512 | F45: =F28/(E4) -> 0.0028553337 | G45: =G28/(F4) -> -0.020845258 | H45: =H28/(G4) -> -0.092576377 | I45: =I28/(H4) -> 0.10219122 | J45: =J28/(I4) -> 0.0047252855 | ... W45: =W28/(V4) -> -0.11373189 | X45: =AVERAGE(C45:W45)*4 -> 0.14901256
...

Sheet Monthly
A1: Month | B1: 2021-01 | C1: 2021-02 | D1: 2021-03 | E1: 2021-04 | F1: 2021-05 | G1: 2021-06 | H1: 2021-07 | I1: 2021-08 | J1: 2021-09 | K1: 2021-10 | L1: 2021-11 | M1: 2021-12 | N1: 2022-01 | O1: 2022-02 | P1: 2022-03 | Q1: 2022-04 | R1: 2022-05 | S1: 2022-06 | T1: 2022-07 | U1: 2022-08 | V1: 2022-09 | W1: 2022-10 | X1: 2022-11 | Y1: 2022-12 | Z1: 2023-01 | AA1: 2023-02 | AB1: 2023-03 | AC1: 2023-04 | AD1: 2023-05 | AE1: 2023-06 | AF1: 2023-07 | AG1: 2023-08 | AH1: 2023-09 | AI1: 2023-10 | AJ1: 2023-11 | AK1: 2023-12 | AL1: 2024-01 | AM1: 2024-02 | AN1: 2024-03 | AO1: 2024-04 | AP1: 2024-05 | AQ1: 2024-06 | AR1: 2024-07 | AS1: 2024-08 | AT1: 2024-09 | AU1: 2024-10 | AV1: 2024-11 | AW1: 2024-12 | AX1: 2025-01 | AY1: 2025-02 | AZ1: 2025-03 | BA1: 2025-04 | BB1: 2025-05 | BC1: 2025-06 | BD1: 2025-07 | BE1: 2025-08 | BF1: 2025-09 | BG1: 2025-10 | BH1: 2025-11 | BI1: 2025-12 | BJ1: 2026-01 | BK1: 2026-02 | BL1: 2026-03 | BM1: 2026-04 | BN1: 2026-05 | BO1: =COUNTA($B1:BN1)-1 -> 64
B2: Value (L) | C2: Value (L) | D2: Value (L) | E2: Value (L) | F2: Value (L) | G2: Value (L) | H2: Value (L) | I2: Value (L) | J2: Value (L) | K2: Value (L) | L2: Value (L) | M2: Value (L) | N2: Value (L) | O2: Value (L) | P2: Value (L) | Q2: Value (L) | R2: Value (L) | S2: Value (L) | T2: Value (L) | U2: Value (L) | V2: Value (L) | W2: Value (L) | X2: Value (L) | Y2: Value (L) | Z2: Value (L) | AA2: Value (L) | AB2: Value (L) | AC2: Value (L) | AD2: Value (L) | AE2: Value (L) | AF2: Value (L) | AG2: Value (L) | AH2: Value (L) | AI2: Value (L) | AJ2: Value (L) | AK2: Value (L) | AL2: Value (L) | AM2: Value (L) | AN2: Value (L) | AO2: Value (L) | AP2: Value (L) | AQ2: Value (L) | AR2: Value (L) | AS2: Value (L) | AT2: Value (L) | AU2: Value (L) | AV2: Value (L) | AW2: Value (L) | AX2: Value (L) | AY2: Value (L) | AZ2: Value (L) | BA2: Value (L) | BB2: Value (L) | BC2: Value (L) | BD2: Value (L) | BE2: Value (L) | BF2: Value (L) | BG2: Value (L) | BH2: Value (L) | BI2: Value (L) | BJ2: Value (L) | BK2: Value (L) | BL2: Value (L) | BM2: Value (L) | BN2: Value (L) | BO2: CAGR | BP2: TOTAL | BQ2: AVERAGE
A3: NET WORTH
A4: Equity | B4: =SUMIF(Breakup!$B$4:$C$14,Monthly!$A4,Breakup!$C$4:$C$14) -> 45.920595 | C4: =SUMIF(Breakup!$B$4:D$14,Monthly!$A4,Breakup!D$4:D$14) -> 49.854466 | D4: =SUMIF(Breakup!$B$4:E$14,Monthly!$A4,Breakup!E$4:E$14) -> 54.495787 | E4: =SUMIF(Breakup!$B$4:F$14,Monthly!$A4,Breakup!F$4:F$14) -> 55.636562 | F4: =SUMIF(Breakup!$B$4:G$14,Monthly!$A4,Breakup!G$4:G$14) -> 54.207659 | G4: =SUMIF(Breakup!$B$4:H$14,Monthly!$A4,Breakup!H$4:H$14) -> 60.628057 | H4: =SUMIF(Breakup!$B$4:$L$14,Monthly!$A4,Breakup!$I$4:$I$14) -> 64.627927 | I4: =SUMIF(Breakup!$B$4:$L$14,Monthly!$A4,Breakup!$J$4:$J$14) -> 68.497238 | J4: =SUMIF(Breakup!$B$4:$L$14,Monthly!$A4,Breakup!$K$4:$K$14) -> 74.895077 | K4: =SUMIF(Breakup!$B$4:$L$14,Monthly!$A4,Breakup!L$4:L$14) -> 78.201752 | L4: =SUMIF(Breakup!$B$4:M$14,Monthly!$A4,Breakup!M$4:M$14) -> 80.991219 | M4: =SUMIF(Breakup!$B$4:N$14,Monthly!$A4,Breakup!N$4:N$14) -> 82.479767 | N4: =SUMIF(Breakup!$B$4:O$14,Monthly!$A4,Breakup!O$4:O$14) -> 85.270469 | O4: =SUMIF(Breakup!$B$4:P$14,Monthly!$A4,Breakup!P$4:P$14) -> 87.990961 | P4: =SUMIF(Breakup!$B$4:Q$14,Monthly!$A4,Breakup!Q$4:Q$14) -> 81.655621 | Q4: =SUMIF(Breakup!$B$4:R$14,Monthly!$A4,Breakup!R$4:R$14) -> 88.963405 | R4: =SUMIF(Breakup!$B$4:S$14,Monthly!$A4,Breakup!S$4:S$14) -> 88.984977 | S4: =SUMIF(Breakup!$B$4:T$14,Monthly!$A4,Breakup!T$4:T$14) -> 85.39092 | ... BN4: =SUMIF(Breakup!$B$4:BO$14,Monthly!$A4,Breakup!BO$4:BO$14) -> 252.65671 | BO4: =((BN4/B4)^(12/$BO$1)-1) -> 0.37672793
A5: Debt | B5: =SUMIF(Breakup!$B$4:$C$14,Monthly!$A5,Breakup!$C$4:$C$14) -> 32.53 | C5: =SUMIF(Breakup!$B$4:D$14,Monthly!$A5,Breakup!D$4:D$14) -> 32.998 | D5: =SUMIF(Breakup!$B$4:E$14,Monthly!$A5,Breakup!E$4:E$14) -> 33.43 | E5: =SUMIF(Breakup!$B$4:F$14,Monthly!$A5,Breakup!F$4:F$14) -> 36.019 | F5: =SUMIF(Breakup!$B$4:G$14,Monthly!$A5,Breakup!G$4:G$14) -> 36.8784 | G5: =SUMIF(Breakup!$B$4:H$14,Monthly!$A5,Breakup!H$4:H$14) -> 37.1199 | H5: =SUMIF(Breakup!$B$4:$L$14,Monthly!$A5,Breakup!$I$4:$I$14) -> 37.34856 | I5: =SUMIF(Breakup!$B$4:$L$14,Monthly!$A5,Breakup!$J$4:$J$14) -> 37.58785 | J5: =SUMIF(Breakup!$B$4:$L$14,Monthly!$A5,Breakup!$K$4:$K$14) -> 37.8518 | K5: =SUMIF(Breakup!$B$4:$L$14,Monthly!$A5,Breakup!L$4:L$14) -> 39.71884 | L5: =SUMIF(Breakup!$B$4:M$14,Monthly!$A5,Breakup!M$4:M$14) -> 39.98014 | M5: =SUMIF(Breakup!$B$4:N$14,Monthly!$A5,Breakup!N$4:N$14) -> 40.27544 | N5: =SUMIF(Breakup!$B$4:O$14,Monthly!$A5,Breakup!O$4:O$14) -> 40.56374 | O5: =SUMIF(Breakup!$B$4:P$14,Monthly!$A5,Breakup!P$4:P$14) -> 40.81904 | P5: =SUMIF(Breakup!$B$4:Q$14,Monthly!$A5,Breakup!Q$4:Q$14) -> 41.10534 | Q5: =SUMIF(Breakup!$B$4:R$14,Monthly!$A5,Breakup!R$4:R$14) -> 44.31114 | R5: =SUMIF(Breakup!$B$4:S$14,Monthly!$A5,Breakup!S$4:S$14) -> 44.76894 | S5: =SUMIF(Breakup!$B$4:T$14,Monthly!$A5,Breakup!T$4:T$14) -> 45.00424 | ... BN5: =SUMIF(Breakup!$B$4:BO$14,Monthly!$A5,Breakup!BO$4:BO$14) -> 89.82086 | BO5: =((BN5/B5)^(12/$BO$1)-1) -> 0.209776
A6: Gold | B6: =SUMIF(Breakup!$B$4:$C$14,Monthly!$A6,Breakup!$C$4:$C$14) -> 1 | C6: =SUMIF(Breakup!$B$4:D$14,Monthly!$A6,Breakup!D$4:D$14) -> 1.226364 | D6: =SUMIF(Breakup!$B$4:E$14,Monthly!$A6,Breakup!E$4:E$14) -> 1.179125 | E6: =SUMIF(Breakup!$B$4:F$14,Monthly!$A6,Breakup!F$4:F$14) -> 1.1650255 | F6: =SUMIF(Breakup!$B$4:G$14,Monthly!$A6,Breakup!G$4:G$14) -> 1.19255 | G6: =SUMIF(Breakup!$B$4:H$14,Monthly!$A6,Breakup!H$4:H$14) -> 1.2122535 | H6: =SUMIF(Breakup!$B$4:$L$14,Monthly!$A6,Breakup!$I$4:$I$14) -> 1.1951 | I6: =SUMIF(Breakup!$B$4:$L$14,Monthly!$A6,Breakup!$J$4:$J$14) -> 1.1909635 | J6: =SUMIF(Breakup!$B$4:$L$14,Monthly!$A6,Breakup!$K$4:$K$14) -> 1.177498 | K6: =SUMIF(Breakup!$B$4:$L$14,Monthly!$A6,Breakup!L$4:L$14) -> 1.17335 | L6: =SUMIF(Breakup!$B$4:M$14,Monthly!$A6,Breakup!M$4:M$14) -> 1.1836 | M6: =SUMIF(Breakup!$B$4:N$14,Monthly!$A6,Breakup!N$4:N$14) -> 1.187 | N6: =SUMIF(Breakup!$B$4:O$14,Monthly!$A6,Breakup!O$4:O$14) -> 1.182 | O6: =SUMIF(Breakup!$B$4:P$14,Monthly!$A6,Breakup!P$4:P$14) -> 1.17315 | P6: =SUMIF(Breakup!$B$4:Q$14,Monthly!$A6,Breakup!Q$4:Q$14) -> 1.20425 | Q6: =SUMIF(Breakup!$B$4:R$14,Monthly!$A6,Breakup!R$4:R$14) -> 1.18455 | R6: =SUMIF(Breakup!$B$4:S$14,Monthly!$A6,Breakup!S$4:S$14) -> 1.2309 | S6: =SUMIF(Breakup!$B$4:T$14,Monthly!$A6,Breakup!T$4:T$14) -> 1.1956 | ... BN6: =SUMIF(Breakup!$B$4:BO$14,Monthly!$A6,Breakup!BO$4:BO$14) -> 5.1860555 | BO6: =((BN6/B6)^(12/$BO$1)-1) -> 0.3615449
A7: Alternate | B7: =SUMIF(Breakup!$B$4:$C$14,Monthly!$A7,Breakup!$C$4:$C$14) -> 0 | C7: =SUMIF(Breakup!$B$4:D$14,Monthly!$A7,Breakup!D$4:D$14) -> 0 | D7: =SUMIF(Breakup!$B$4:E$14,Monthly!$A7,Breakup!E$4:E$14) -> 0 | E7: =SUMIF(Breakup!$B$4:F$14,Monthly!$A7,Breakup!F$4:F$14) -> 0 | F7: =SUMIF(Breakup!$B$4:G$14,Monthly!$A7,Breakup!G$4:G$14) -> 0 | G7: =SUMIF(Breakup!$B$4:H$14,Monthly!$A7,Breakup!H$4:H$14) -> 0 | H7: =SUMIF(Breakup!$B$4:$L$14,Monthly!$A7,Breakup!$I$4:$I$14) -> 0 | I7: =SUMIF(Breakup!$B$4:$L$14,Monthly!$A7,Breakup!$J$4:$J$14) -> 0 | J7: =SUMIF(Breakup!$B$4:$L$14,Monthly!$A7,Breakup!$K$4:$K$14) -> 0.10485 | K7: =SUMIF(Breakup!$B$4:$L$14,Monthly!$A7,Breakup!L$4:L$14) -> 0.54 | L7: =SUMIF(Breakup!$B$4:M$14,Monthly!$A7,Breakup!M$4:M$14) -> 0.73 | M7: =SUMIF(Breakup!$B$4:N$14,Monthly!$A7,Breakup!N$4:N$14) -> 0 | N7: =SUMIF(Breakup!$B$4:O$14,Monthly!$A7,Breakup!O$4:O$14) -> 0 | O7: =SUMIF(Breakup!$B$4:P$14,Monthly!$A7,Breakup!P$4:P$14) -> 0 | P7: =SUMIF(Breakup!$B$4:Q$14,Monthly!$A7,Breakup!Q$4:Q$14) -> 0 | Q7: =SUMIF(Breakup!$B$4:R$14,Monthly!$A7,Breakup!R$4:R$14) -> 0 | R7: =SUMIF(Breakup!$B$4:S$14,Monthly!$A7,Breakup!S$4:S$14) -> 0 | S7: =SUMIF(Breakup!$B$4:T$14,Monthly!$A7,Breakup!T$4:T$14) -> 0 | ... BN7: =SUMIF(Breakup!$B$4:BO$14,Monthly!$A7,Breakup!BO$4:BO$14) -> 0
A8: Liquid | B8: =SUMIF(Breakup!$B$4:$C$14,Monthly!$A8,Breakup!$C$4:$C$14) -> 4.65 | C8: =SUMIF(Breakup!$B$4:D$14,Monthly!$A8,Breakup!D$4:D$14) -> 3.2 | D8: =SUMIF(Breakup!$B$4:E$14,Monthly!$A8,Breakup!E$4:E$14) -> 1 | E8: =SUMIF(Breakup!$B$4:F$14,Monthly!$A8,Breakup!F$4:F$14) -> 1.0035016 | F8: =SUMIF(Breakup!$B$4:G$14,Monthly!$A8,Breakup!G$4:G$14) -> 3.5108187 | G8: =SUMIF(Breakup!$B$4:H$14,Monthly!$A8,Breakup!H$4:H$14) -> 3.5198853 | H8: =SUMIF(Breakup!$B$4:$L$14,Monthly!$A8,Breakup!$I$4:$I$14) -> 3.5291139 | I8: =SUMIF(Breakup!$B$4:$L$14,Monthly!$A8,Breakup!$J$4:$J$14) -> 2.538389 | J8: =SUMIF(Breakup!$B$4:$L$14,Monthly!$A8,Breakup!$K$4:$K$14) -> 2.0454896 | K8: =SUMIF(Breakup!$B$4:$L$14,Monthly!$A8,Breakup!L$4:L$14) -> 4.3487874 | L8: =SUMIF(Breakup!$B$4:M$14,Monthly!$A8,Breakup!M$4:M$14) -> 3.3509365 | M8: =SUMIF(Breakup!$B$4:N$14,Monthly!$A8,Breakup!N$4:N$14) -> 2.3510604 | N8: =SUMIF(Breakup!$B$4:O$14,Monthly!$A8,Breakup!O$4:O$14) -> 2.8575657 | O8: =SUMIF(Breakup!$B$4:P$14,Monthly!$A8,Breakup!P$4:P$14) -> 2.3574783 | P8: =SUMIF(Breakup!$B$4:Q$14,Monthly!$A8,Breakup!Q$4:Q$14) -> 1.3439699 | Q8: =SUMIF(Breakup!$B$4:R$14,Monthly!$A8,Breakup!R$4:R$14) -> 1.347861 | R8: =SUMIF(Breakup!$B$4:S$14,Monthly!$A8,Breakup!S$4:S$14) -> 1.3516378 | S8: =SUMIF(Breakup!$B$4:T$14,Monthly!$A8,Breakup!T$4:T$14) -> 3.2196e-05 | ... BN8: =SUMIF(Breakup!$B$4:BO$14,Monthly!$A8,Breakup!BO$4:BO$14) -> 0
A9: Total | B9: =SUM(B4:B8) -> 84.100595 | C9: =SUM(C4:C8) -> 87.27883 | D9: =SUM(D4:D8) -> 90.104912 | E9: =SUM(E4:E8) -> 93.824089 | F9: =SUM(F4:F8) -> 95.789428 | G9: =SUM(G4:G8) -> 102.4801 | H9: =SUM(H4:H8) -> 106.7007 | I9: =SUM(I4:I8) -> 109.81444 | ... BN9: =SUM(BN4:BN8) -> 347.66362 | BO9: =((BN9/B9)^(12/$BO$1)-1) -> 0.30487087
A11: CONTRIBUTION
A12: Equity | B12: =B4/B$9 -> 0.54601986 | C12: =C4/C$9 -> 0.57120915 | D12: =D4/D$9 -> 0.60480373 | E12: =E4/E$9 -> 0.59298803 | F12: =F4/F$9 -> 0.5659044 | G12: =G4/G$9 -> 0.59160812 | H12: =H4/H$9 -> 0.60569356 | I12: =I4/I$9 -> 0.62375438 | ... BN12: =BN4/BN$9 -> 0.72672748
A13: Debt | B13: =B5/B$9 -> 0.38679869 | C13: =C5/C$9 -> 0.37807564 | D13: =D5/D$9 -> 0.37101196 | E13: =E5/E$9 -> 0.38389928 | F13: =F5/F$9 -> 0.38499447 | G13: =G5/G$9 -> 0.3622157 | H13: =H5/H$9 -> 0.35003106 | I13: =I5/I$9 -> 0.34228513 | ... BN13: =BN5/BN$9 -> 0.25835565
A14: Gold | B14: =B6/B$9 -> 0.011890522 | C14: =C6/C$9 -> 0.014051105 | D14: =D6/D$9 -> 0.013086135 | E14: =E6/E$9 -> 0.012417126 | F14: =F6/F$9 -> 0.012449704 | G14: =G6/G$9 -> 0.01182916 | H14: =H6/H$9 -> 0.011200489 | I14: =I6/I$9 -> 0.010845236 | ... BN14: =BN6/BN$9 -> 0.014916877
A15: Alternate | B15: =B7/B$9 -> 0 | C15: =C7/C$9 -> 0 | D15: =D7/D$9 -> 0 | E15: =E7/E$9 -> 0 | F15: =F7/F$9 -> 0 | G15: =G7/G$9 -> 0 | H15: =H7/H$9 -> 0 | I15: =I7/I$9 -> 0 | ... BN15: =BN7/BN$9 -> 0
A16: Liquid | B16: =B8/B$9 -> 0.055290929 | C16: =C8/C$9 -> 0.036664103 | D16: =D8/D$9 -> 0.011098174 | E16: =E8/E$9 -> 0.010695565 | F16: =F8/F$9 -> 0.036651422 | G16: =G8/G$9 -> 0.034347014 | H16: =H8/H$9 -> 0.033074889 | I16: =I8/I$9 -> 0.023115257 | ... BN16: =BN8/BN$9 -> 0
A17: Total | B17: =SUM(B12:B16) -> 1 | C17: =SUM(C12:C16) -> 1 | D17: =SUM(D12:D16) -> 1 | E17: =SUM(E12:E16) -> 1 | F17: =SUM(F12:F16) -> 1 | G17: =SUM(G12:G16) -> 1 | H17: =SUM(H12:H16) -> 1 | I17: =SUM(I12:I16) -> 1 | ... BN17: =SUM(BN12:BN16) -> 1
A19: NEW INVESTMENT
A20: Equity | B20: =SUMIF(Breakup!$B$30:$L$40,Monthly!$A20,Breakup!C$30:C$40) -> 0 | C20: =SUMIF(Breakup!$B$30:$L$40,Monthly!$A20,Breakup!D$30:D$40) -> 1.8463708 | D20: =SUMIF(Breakup!$B$30:$L$40,Monthly!$A20,Breakup!E$30:E$40) -> 0.41 | E20: =SUMIF(Breakup!$B$30:$L$40,Monthly!$A20,Breakup!F$30:F$40) -> 2 | F20: =SUMIF(Breakup!$B$30:$L$40,Monthly!$A20,Breakup!G$30:G$40) -> -1.73 | G20: =SUMIF(Breakup!$B$30:$L$40,Monthly!$A20,Breakup!H$30:H$40) -> 1.9 | H20: =SUMIF(Breakup!$B$30:$L$40,Monthly!$A20,Breakup!I$30:I$40) -> 2.43 | I20: =SUMIF(Breakup!$B$30:$L$40,Monthly!$A20,Breakup!J$30:J$40) -> 1.6 | ... K20: =SUMIF(Breakup!$B$30:$L$40,Monthly!$A20,Breakup!L$30:L$40) -> 2.1903996 | L20: =SUMIF(Breakup!$B$30:M$40,Monthly!$A20,Breakup!M$30:M$40) -> 2.0379246 | M20: =SUMIF(Breakup!$B$30:N$40,Monthly!$A20,Breakup!N$30:N$40) -> 2.7206581 | N20: =SUMIF(Breakup!$B$30:O$40,Monthly!$A20,Breakup!O$30:O$40) -> 2.086842 | O20: =SUMIF(Breakup!$B$30:P$40,Monthly!$A20,Breakup!P$30:P$40) -> 2.3892298 | P20: =SUMIF(Breakup!$B$30:Q$40,Monthly!$A20,Breakup!Q$30:Q$40) -> 1.2756248 | Q20: =SUMIF(Breakup!$B$30:R$40,Monthly!$A20,Breakup!R$30:R$40) -> 1.8055663 | R20: =SUMIF(Breakup!$B$30:S$40,Monthly!$A20,Breakup!S$30:S$40) -> 1.2465006 | S20: =SUMIF(Breakup!$B$30:T$40,Monthly!$A20,Breakup!T$30:T$40) -> 0.43181348 | ... U20: =SUMIF(Breakup!$B$30:V$40,Monthly!$A20,Breakup!V$30:V$40) -> 0.84336885 | V20: =SUMIF(Breakup!$B$30:BO$40,Monthly!$A20,Breakup!W$30:W$40) -> 1.34439 | W20: =SUMIF(Breakup!$B$30:BP$40,Monthly!$A20,Breakup!X$30:X$40) -> 2.7955833 | X20: =SUMIF(Breakup!$B$30:Y$40,Monthly!$A20,Breakup!Y$30:Y$40) -> 3.1684778 | Y20: =SUMIF(Breakup!$B$30:Z$40,Monthly!$A20,Breakup!Z$30:Z$40) -> 3.1684778 | Z20: =SUMIF(Breakup!$B$30:AA$40,Monthly!$A20,Breakup!AA$30:AA$40) -> 1.0860967 | AA20: =SUMIF(Breakup!$B$30:AB$40,Monthly!$A20,Breakup!AB$30:AB$40) -> 3.0482444 | AB20: =SUMIF(Breakup!$B$30:AC$40,Monthly!$A20,Breakup!AC$30:AC$40) -> 3.0482444 | AC20: =SUMIF(Breakup!$B$30:AD$40,Monthly!$A20,Breakup!AD$30:AD$40) -> 1.0771129 | AD20: =SUMIF(Breakup!$B$30:AE$40,Monthly!$A20,Breakup!AE$30:AE$40) -> 2.6104181 | AE20: =SUMIF(Breakup!$B$30:AF$40,Monthly!$A20,Breakup!AF$30:AF$40) -> 0.46110399 | ... BN20: =SUMIF(Breakup!$B$30:BO$40,Monthly!$A20,Breakup!BO$30:BO$40) -> 0.050001218 | BP20: =SUM(B20:BN20) -> 109.43943 | BQ20: =BP20/$BO$1 -> 1.709991
A21: Debt | B21: =SUMIF(Breakup!$B$30:$L$40,Monthly!$A21,Breakup!C$30:C$40) -> 0 | C21: =SUMIF(Breakup!$B$30:$L$40,Monthly!$A21,Breakup!D$30:D$40) -> 0.23 | D21: =SUMIF(Breakup!$B$30:$L$40,Monthly!$A21,Breakup!E$30:E$40) -> 0.47 | E21: =SUMIF(Breakup!$B$30:$L$40,Monthly!$A21,Breakup!F$30:F$40) -> 0.2 | F21: =SUMIF(Breakup!$B$30:$L$40,Monthly!$A21,Breakup!G$30:G$40) -> 0.23 | G21: =SUMIF(Breakup!$B$30:$L$40,Monthly!$A21,Breakup!H$30:H$40) -> 0.233 | H21: =SUMIF(Breakup!$B$30:$L$40,Monthly!$A21,Breakup!I$30:I$40) -> 0.23296 | I21: =SUMIF(Breakup!$B$30:$L$40,Monthly!$A21,Breakup!J$30:J$40) -> 0.23296 | ... K21: =SUMIF(Breakup!$B$30:$L$40,Monthly!$A21,Breakup!L$30:L$40) -> 1.88296 | L21: =SUMIF(Breakup!$B$30:M$40,Monthly!$A21,Breakup!M$30:M$40) -> 0.2753 | M21: =SUMIF(Breakup!$B$30:N$40,Monthly!$A21,Breakup!N$30:N$40) -> 0.2753 | N21: =SUMIF(Breakup!$B$30:O$40,Monthly!$A21,Breakup!O$30:O$40) -> 0.2753 | O21: =SUMIF(Breakup!$B$30:P$40,Monthly!$A21,Breakup!P$30:P$40) -> 0.2753 | P21: =SUMIF(Breakup!$B$30:Q$40,Monthly!$A21,Breakup!Q$30:Q$40) -> 0.2753 | Q21: =SUMIF(Breakup!$B$30:R$40,Monthly!$A21,Breakup!R$30:R$40) -> 0.2858 | R21: =SUMIF(Breakup!$B$30:S$40,Monthly!$A21,Breakup!S$30:S$40) -> 0.2753 | S21: =SUMIF(Breakup!$B$30:T$40,Monthly!$A21,Breakup!T$30:T$40) -> 0.2753 | ... U21: =SUMIF(Breakup!$B$30:V$40,Monthly!$A21,Breakup!V$30:V$40) -> 0.298304 | V21: =SUMIF(Breakup!$B$30:BO$40,Monthly!$A21,Breakup!W$30:W$40) -> 1.925446 | W21: =SUMIF(Breakup!$B$30:BP$40,Monthly!$A21,Breakup!X$30:X$40) -> 0.271544 | X21: =SUMIF(Breakup!$B$30:Y$40,Monthly!$A21,Breakup!Y$30:Y$40) -> 0.281408 | Y21: =SUMIF(Breakup!$B$30:Z$40,Monthly!$A21,Breakup!Z$30:Z$40) -> 0.618688 | Z21: =SUMIF(Breakup!$B$30:AA$40,Monthly!$A21,Breakup!AA$30:AA$40) -> 0.3185 | AA21: =SUMIF(Breakup!$B$30:AB$40,Monthly!$A21,Breakup!AB$30:AB$40) -> 0.3185 | AB21: =SUMIF(Breakup!$B$30:AC$40,Monthly!$A21,Breakup!AC$30:AC$40) -> 0.3185 | AC21: =SUMIF(Breakup!$B$30:AD$40,Monthly!$A21,Breakup!AD$30:AD$40) -> 0.3 | AD21: =SUMIF(Breakup!$B$30:AE$40,Monthly!$A21,Breakup!AE$30:AE$40) -> 0.3185 | AE21: =SUMIF(Breakup!$B$30:AF$40,Monthly!$A21,Breakup!AF$30:AF$40) -> 0.3185 | ... BN21: =SUMIF(Breakup!$B$30:BO$40,Monthly!$A21,Breakup!BO$30:BO$40) -> 0.47506 | BP21: =SUM(B21:BN21) -> 30.68847 | BQ21: =BP21/$BO$1 -> 0.47950734
A22: Gold | B22: =SUMIF(Breakup!$B$30:$L$40,Monthly!$A22,Breakup!C$30:C$40) -> 0 | C22: =SUMIF(Breakup!$B$30:$L$40,Monthly!$A22,Breakup!D$30:D$40) -> 0.2475 | D22: =SUMIF(Breakup!$B$30:$L$40,Monthly!$A22,Breakup!E$30:E$40) -> 0 | E22: =SUMIF(Breakup!$B$30:$L$40,Monthly!$A22,Breakup!F$30:F$40) -> 0 | F22: =SUMIF(Breakup!$B$30:$L$40,Monthly!$A22,Breakup!G$30:G$40) -> 0 | G22: =SUMIF(Breakup!$B$30:$L$40,Monthly!$A22,Breakup!H$30:H$40) -> 0 | H22: =SUMIF(Breakup!$B$30:$L$40,Monthly!$A22,Breakup!I$30:I$40) -> 0 | I22: =SUMIF(Breakup!$B$30:$L$40,Monthly!$A22,Breakup!J$30:J$40) -> 0 | ... K22: =SUMIF(Breakup!$B$30:$L$40,Monthly!$A22,Breakup!L$30:L$40) -> 0 | L22: =SUMIF(Breakup!$B$30:M$40,Monthly!$A22,Breakup!M$30:M$40) -> 0 | M22: =SUMIF(Breakup!$B$30:N$40,Monthly!$A22,Breakup!N$30:N$40) -> 0 | N22: =SUMIF(Breakup!$B$30:O$40,Monthly!$A22,Breakup!O$30:O$40) -> 0 | O22: =SUMIF(Breakup!$B$30:P$40,Monthly!$A22,Breakup!P$30:P$40) -> 0 | P22: =SUMIF(Breakup!$B$30:Q$40,Monthly!$A22,Breakup!Q$30:Q$40) -> 0 | Q22: =SUMIF(Breakup!$B$30:R$40,Monthly!$A22,Breakup!R$30:R$40) -> -0.0197 | R22: =SUMIF(Breakup!$B$30:S$40,Monthly!$A22,Breakup!S$30:S$40) -> 0.04635 | S22: =SUMIF(Breakup!$B$30:T$40,Monthly!$A22,Breakup!T$30:T$40) -> -0.0353 | ... U22: =SUMIF(Breakup!$B$30:V$40,Monthly!$A22,Breakup!V$30:V$40) -> -0.00159 | V22: =SUMIF(Breakup!$B$30:BO$40,Monthly!$A22,Breakup!W$30:W$40) -> 0 | W22: =SUMIF(Breakup!$B$30:BP$40,Monthly!$A22,Breakup!X$30:X$40) -> 0 | X22: =SUMIF(Breakup!$B$30:Y$40,Monthly!$A22,Breakup!Y$30:Y$40) -> 0 | Y22: =SUMIF(Breakup!$B$30:Z$40,Monthly!$A22,Breakup!Z$30:Z$40) -> 0 | Z22: =SUMIF(Breakup!$B$30:AA$40,Monthly!$A22,Breakup!AA$30:AA$40) -> 0 | AA22: =SUMIF(Breakup!$B$30:AB$40,Monthly!$A22,Breakup!AB$30:AB$40) -> 0 | AB22: =SUMIF(Breakup!$B$30:AC$40,Monthly!$A22,Breakup!AC$30:AC$40) -> 0 | AC22: =SUMIF(Breakup!$B$30:AD$40,Monthly!$A22,Breakup!AD$30:AD$40) -> 0 | AD22: =SUMIF(Breakup!$B$30:AE$40,Monthly!$A22,Breakup!AE$30:AE$40) -> 0 | AE22: =SUMIF(Breakup!$B$30:AF$40,Monthly!$A22,Breakup!AF$30:AF$40) -> 0 | ... BN22: =SUMIF(Breakup!$B$30:BO$40,Monthly!$A22,Breakup!BO$30:BO$40) -> 0 | BP22: =SUM(B22:BN22) -> 1.25266 | BQ22: =BP22/$BO$1 -> 0.019572813
A23: Alternate | B23: =SUMIF(Breakup!$B$30:$L$40,Monthly!$A23,Breakup!C$30:C$40) -> 0 | C23: =SUMIF(Breakup!$B$30:$L$40,Monthly!$A23,Breakup!D$30:D$40) -> 0 | D23: =SUMIF(Breakup!$B$30:$L$40,Monthly!$A23,Breakup!E$30:E$40) -> 0 | E23: =SUMIF(Breakup!$B$30:$L$40,Monthly!$A23,Breakup!F$30:F$40) -> 0 | F23: =SUMIF(Breakup!$B$30:$L$40,Monthly!$A23,Breakup!G$30:G$40) -> 0 | G23: =SUMIF(Breakup!$B$30:$L$40,Monthly!$A23,Breakup!H$30:H$40) -> 0 | H23: =SUMIF(Breakup!$B$30:$L$40,Monthly!$A23,Breakup!I$30:I$40) -> 0 | I23: =SUMIF(Breakup!$B$30:$L$40,Monthly!$A23,Breakup!J$30:J$40) -> 0 | ... K23: =SUMIF(Breakup!$B$30:$L$40,Monthly!$A23,Breakup!L$30:L$40) -> 0.43515 | L23: =SUMIF(Breakup!$B$30:M$40,Monthly!$A23,Breakup!M$30:M$40) -> 0 | M23: =SUMIF(Breakup!$B$30:N$40,Monthly!$A23,Breakup!N$30:N$40) -> -0.73 | N23: =SUMIF(Breakup!$B$30:O$40,Monthly!$A23,Breakup!O$30:O$40) -> 0 | O23: =SUMIF(Breakup!$B$30:P$40,Monthly!$A23,Breakup!P$30:P$40) -> 0 | P23: =SUMIF(Breakup!$B$30:Q$40,Monthly!$A23,Breakup!Q$30:Q$40) -> 0 | Q23: =SUMIF(Breakup!$B$30:R$40,Monthly!$A23,Breakup!R$30:R$40) -> 0 | R23: =SUMIF(Breakup!$B$30:S$40,Monthly!$A23,Breakup!S$30:S$40) -> 0 | S23: =SUMIF(Breakup!$B$30:T$40,Monthly!$A23,Breakup!T$30:T$40) -> 0 | ... U23: =SUMIF(Breakup!$B$30:V$40,Monthly!$A23,Breakup!V$30:V$40) -> 0 | V23: =SUMIF(Breakup!$B$30:BO$40,Monthly!$A23,Breakup!W$30:W$40) -> 0 | W23: =SUMIF(Breakup!$B$30:BP$40,Monthly!$A23,Breakup!X$30:X$40) -> 0 | X23: =SUMIF(Breakup!$B$30:Y$40,Monthly!$A23,Breakup!Y$30:Y$40) -> 0 | Y23: =SUMIF(Breakup!$B$30:Z$40,Monthly!$A23,Breakup!Z$30:Z$40) -> 0 | Z23: =SUMIF(Breakup!$B$30:AA$40,Monthly!$A23,Breakup!AA$30:AA$40) -> 0 | AA23: =SUMIF(Breakup!$B$30:AB$40,Monthly!$A23,Breakup!AB$30:AB$40) -> 0 | AB23: =SUMIF(Breakup!$B$30:AC$40,Monthly!$A23,Breakup!AC$30:AC$40) -> 0 | AC23: =SUMIF(Breakup!$B$30:AD$40,Monthly!$A23,Breakup!AD$30:AD$40) -> 0 | AD23: =SUMIF(Breakup!$B$30:AE$40,Monthly!$A23,Breakup!AE$30:AE$40) -> 0 | AE23: =SUMIF(Breakup!$B$30:AF$40,Monthly!$A23,Breakup!AF$30:AF$40) -> 0 | ... BN23: =SUMIF(Breakup!$B$30:BO$40,Monthly!$A23,Breakup!BO$30:BO$40) -> 0 | BP23: =SUM(B23:BN23) -> -0.19 | BQ23: =BP23/$BO$1 -> -0.00296875
A24: Liquid | B24: =SUMIF(Breakup!$B$30:$L$40,Monthly!$A24,Breakup!C$30:C$40) -> 0 | C24: =SUMIF(Breakup!$B$30:$L$40,Monthly!$A24,Breakup!D$30:D$40) -> -1.45 | D24: =SUMIF(Breakup!$B$30:$L$40,Monthly!$A24,Breakup!E$30:E$40) -> -2.2 | E24: =SUMIF(Breakup!$B$30:$L$40,Monthly!$A24,Breakup!F$30:F$40) -> 0.003501614 | F24: =SUMIF(Breakup!$B$30:$L$40,Monthly!$A24,Breakup!G$30:G$40) -> 2.5073171 | G24: =SUMIF(Breakup!$B$30:$L$40,Monthly!$A24,Breakup!H$30:H$40) -> 0.009066541 | H24: =SUMIF(Breakup!$B$30:$L$40,Monthly!$A24,Breakup!I$30:I$40) -> 0.009228589 | I24: =SUMIF(Breakup!$B$30:$L$40,Monthly!$A24,Breakup!J$30:J$40) -> -0.99072487 | ... K24: =SUMIF(Breakup!$B$30:$L$40,Monthly!$A24,Breakup!L$30:L$40) -> 2.3032978 | L24: =SUMIF(Breakup!$B$30:M$40,Monthly!$A24,Breakup!M$30:M$40) -> -0.99785091 | M24: =SUMIF(Breakup!$B$30:N$40,Monthly!$A24,Breakup!N$30:N$40) -> -0.99987614 | N24: =SUMIF(Breakup!$B$30:O$40,Monthly!$A24,Breakup!O$30:O$40) -> 0.50650531 | O24: =SUMIF(Breakup!$B$30:P$40,Monthly!$A24,Breakup!P$30:P$40) -> -0.50008737 | P24: =SUMIF(Breakup!$B$30:Q$40,Monthly!$A24,Breakup!Q$30:Q$40) -> -1.0135085 | Q24: =SUMIF(Breakup!$B$30:R$40,Monthly!$A24,Breakup!R$30:R$40) -> 0.003891126 | R24: =SUMIF(Breakup!$B$30:S$40,Monthly!$A24,Breakup!S$30:S$40) -> 0.003776786 | S24: =SUMIF(Breakup!$B$30:T$40,Monthly!$A24,Breakup!T$30:T$40) -> -1.3516056 | ... U24: =SUMIF(Breakup!$B$30:V$40,Monthly!$A24,Breakup!V$30:V$40) -> 0 | V24: =SUMIF(Breakup!$B$30:BO$40,Monthly!$A24,Breakup!W$30:W$40) -> 4 | W24: =SUMIF(Breakup!$B$30:BP$40,Monthly!$A24,Breakup!X$30:X$40) -> -1.5 | X24: =SUMIF(Breakup!$B$30:Y$40,Monthly!$A24,Breakup!Y$30:Y$40) -> -2.5 | Y24: =SUMIF(Breakup!$B$30:Z$40,Monthly!$A24,Breakup!Z$30:Z$40) -> 0 | Z24: =SUMIF(Breakup!$B$30:AA$40,Monthly!$A24,Breakup!AA$30:AA$40) -> 1.5 | AA24: =SUMIF(Breakup!$B$30:AB$40,Monthly!$A24,Breakup!AB$30:AB$40) -> 0 | AB24: =SUMIF(Breakup!$B$30:AC$40,Monthly!$A24,Breakup!AC$30:AC$40) -> 0 | AC24: =SUMIF(Breakup!$B$30:AD$40,Monthly!$A24,Breakup!AD$30:AD$40) -> 1.5 | AD24: =SUMIF(Breakup!$B$30:AE$40,Monthly!$A24,Breakup!AE$30:AE$40) -> -1 | AE24: =SUMIF(Breakup!$B$30:AF$40,Monthly!$A24,Breakup!AF$30:AF$40) -> -1 | ... BN24: =SUMIF(Breakup!$B$30:BO$40,Monthly!$A24,Breakup!BO$30:BO$40) -> 0 | BP24: =SUM(B24:BN24) -> -4.65 | BQ24: =BP24/$BO$1 -> -0.07265625
A25: Total | B25: =SUM(B20:B24) -> 0 | C25: =SUM(C20:C24) -> 0.87387083 | D25: =SUM(D20:D24) -> -1.32 | E25: =SUM(E20:E24) -> 2.2035016 | F25: =SUM(F20:F24) -> 1.0073171 | G25: =SUM(G20:G24) -> 2.1420665 | H25: =SUM(H20:H24) -> 2.6721886 | I25: =SUM(I20:I24) -> 0.84223513 | ... BN25: =SUM(BN20:BN24) -> 0.52506122 | BP25: =SUM(B25:BN25) -> 136.54056 | BQ25: =BP25/$BO$1 -> 2.1334462
A27: RETURNS
A28: Equity | B28: =SUMIF(Breakup!$B$44:$L$54,Monthly!$A28,Breakup!C$44:C$54) -> 0 | C28: =SUMIF(Breakup!$B$44:$L$54,Monthly!$A28,Breakup!D$44:D$54) -> 2.0875006 | D28: =SUMIF(Breakup!$B$44:$L$54,Monthly!$A28,Breakup!E$44:E$54) -> 4.2313206 | E28: =SUMIF(Breakup!$B$44:$L$54,Monthly!$A28,Breakup!F$44:F$54) -> -0.85922524 | F28: =SUMIF(Breakup!$B$44:$L$54,Monthly!$A28,Breakup!G$44:G$54) -> 0.30109744 | G28: =SUMIF(Breakup!$B$44:$L$54,Monthly!$A28,Breakup!H$44:H$54) -> 4.5203984 | H28: =SUMIF(Breakup!$B$44:$L$54,Monthly!$A28,Breakup!I$44:I$54) -> 1.5698698 | I28: =SUMIF(Breakup!$B$44:$L$54,Monthly!$A28,Breakup!J$44:J$54) -> 2.2693108 | ... K28: =SUMIF(Breakup!$B$44:$L$54,Monthly!$A28,Breakup!L$44:L$54) -> 1.1162761 | L28: =SUMIF(Breakup!$B$44:M$54,Monthly!$A28,Breakup!M$44:M$54) -> 0.75154214 | M28: =SUMIF(Breakup!$B$44:N$54,Monthly!$A28,Breakup!N$44:N$54) -> -1.2321105 | N28: =SUMIF(Breakup!$B$44:O$54,Monthly!$A28,Breakup!O$44:O$54) -> 0.70386042 | O28: =SUMIF(Breakup!$B$44:P$54,Monthly!$A28,Breakup!P$44:P$54) -> 0.33126205 | P28: =SUMIF(Breakup!$B$44:Q$54,Monthly!$A28,Breakup!Q$44:Q$54) -> -7.6109648 | Q28: =SUMIF(Breakup!$B$44:R$54,Monthly!$A28,Breakup!R$44:R$54) -> 5.5022179 | R28: =SUMIF(Breakup!$B$44:S$54,Monthly!$A28,Breakup!S$44:S$54) -> -1.2249286 | S28: =SUMIF(Breakup!$B$44:T$54,Monthly!$A28,Breakup!T$44:T$54) -> -4.0258704 | ... U28: =SUMIF(Breakup!$B$44:V$54,Monthly!$A28,Breakup!V$44:V$54) -> 8.1110414 | V28: =SUMIF(Breakup!$B$44:BO$54,Monthly!$A28,Breakup!W$44:W$54) -> 2.4134784 | W28: =SUMIF(Breakup!$B$44:BP$54,Monthly!$A28,Breakup!X$44:X$54) -> -2.0730496 | X28: =SUMIF(Breakup!$B$44:Y$54,Monthly!$A28,Breakup!Y$44:Y$54) -> 3.4267467 | Y28: =SUMIF(Breakup!$B$44:Z$54,Monthly!$A28,Breakup!Z$44:Z$54) -> 0.27717154 | Z28: =SUMIF(Breakup!$B$44:AA$54,Monthly!$A28,Breakup!AA$44:AA$54) -> -3.2496419 | AA28: =SUMIF(Breakup!$B$44:AB$54,Monthly!$A28,Breakup!AB$44:AB$54) -> -0.37346527 | AB28: =SUMIF(Breakup!$B$44:AC$54,Monthly!$A28,Breakup!AC$44:AC$54) -> -0.90731354 | AC28: =SUMIF(Breakup!$B$44:AD$54,Monthly!$A28,Breakup!AD$44:AD$54) -> -1.0894759 | AD28: =SUMIF(Breakup!$B$44:AE$54,Monthly!$A28,Breakup!AE$44:AE$54) -> 5.2529259 | AE28: =SUMIF(Breakup!$B$44:AF$54,Monthly!$A28,Breakup!AF$44:AF$54) -> 6.381625 | ... BN28: =SUMIF(Breakup!$B$44:BO$54,Monthly!$A28,Breakup!BO$44:BO$54) -> 25.625288 | BP28: =SUM(B28:BN28) -> 97.296686 | BQ28: =BP28/$BO$1 -> 1.5202607
A29: Debt | B29: =SUMIF(Breakup!$B$44:$L$54,Monthly!$A29,Breakup!C$44:C$54) -> 0 | C29: =SUMIF(Breakup!$B$44:$L$54,Monthly!$A29,Breakup!D$44:D$54) -> 0.238 | D29: =SUMIF(Breakup!$B$44:$L$54,Monthly!$A29,Breakup!E$44:E$54) -> -0.038 | E29: =SUMIF(Breakup!$B$44:$L$54,Monthly!$A29,Breakup!F$44:F$54) -> 2.389 | F29: =SUMIF(Breakup!$B$44:$L$54,Monthly!$A29,Breakup!G$44:G$54) -> 0.6294 | G29: =SUMIF(Breakup!$B$44:$L$54,Monthly!$A29,Breakup!H$44:H$54) -> 0.0085 | H29: =SUMIF(Breakup!$B$44:$L$54,Monthly!$A29,Breakup!I$44:I$54) -> -0.0043 | I29: =SUMIF(Breakup!$B$44:$L$54,Monthly!$A29,Breakup!J$44:J$54) -> 0.00633 | ... K29: =SUMIF(Breakup!$B$44:$L$54,Monthly!$A29,Breakup!L$44:L$54) -> -0.01592 | L29: =SUMIF(Breakup!$B$44:M$54,Monthly!$A29,Breakup!M$44:M$54) -> -0.014 | M29: =SUMIF(Breakup!$B$44:N$54,Monthly!$A29,Breakup!N$44:N$54) -> 0.02 | N29: =SUMIF(Breakup!$B$44:O$54,Monthly!$A29,Breakup!O$44:O$54) -> 0.013 | O29: =SUMIF(Breakup!$B$44:P$54,Monthly!$A29,Breakup!P$44:P$54) -> -0.02 | P29: =SUMIF(Breakup!$B$44:Q$54,Monthly!$A29,Breakup!Q$44:Q$54) -> 0.011 | Q29: =SUMIF(Breakup!$B$44:R$54,Monthly!$A29,Breakup!R$44:R$54) -> 2.92 | R29: =SUMIF(Breakup!$B$44:S$54,Monthly!$A29,Breakup!S$44:S$54) -> 0.1825 | S29: =SUMIF(Breakup!$B$44:T$54,Monthly!$A29,Breakup!T$44:T$54) -> -0.04 | ... U29: =SUMIF(Breakup!$B$44:V$54,Monthly!$A29,Breakup!V$44:V$54) -> 0.026 | V29: =SUMIF(Breakup!$B$44:BO$54,Monthly!$A29,Breakup!W$44:W$54) -> 0.005 | W29: =SUMIF(Breakup!$B$44:BP$54,Monthly!$A29,Breakup!X$44:X$54) -> 0.038 | X29: =SUMIF(Breakup!$B$44:Y$54,Monthly!$A29,Breakup!Y$44:Y$54) -> -0.009 | Y29: =SUMIF(Breakup!$B$44:Z$54,Monthly!$A29,Breakup!Z$44:Z$54) -> 0.04 | Z29: =SUMIF(Breakup!$B$44:AA$54,Monthly!$A29,Breakup!AA$44:AA$54) -> 0.0066 | AA29: =SUMIF(Breakup!$B$44:AB$54,Monthly!$A29,Breakup!AB$44:AB$54) -> 0.02301 | AB29: =SUMIF(Breakup!$B$44:AC$54,Monthly!$A29,Breakup!AC$44:AC$54) -> 0.001782 | AC29: =SUMIF(Breakup!$B$44:AD$54,Monthly!$A29,Breakup!AD$44:AD$54) -> 3.113448 | AD29: =SUMIF(Breakup!$B$44:AE$54,Monthly!$A29,Breakup!AE$44:AE$54) -> 0.039002 | AE29: =SUMIF(Breakup!$B$44:AF$54,Monthly!$A29,Breakup!AF$44:AF$54) -> 0.038998 | ... BN29: =SUMIF(Breakup!$B$44:BO$54,Monthly!$A29,Breakup!BO$44:BO$54) -> 0.7326 | BP29: =SUM(B29:BN29) -> 26.601676 | BQ29: =BP29/$BO$1 -> 0.41565119
